08/03/2025 09:10:15 PM function setup_training_pipeline called with args 
08/03/2025 09:10:15 PM Device: cpu
08/03/2025 09:10:15 PM Batch size: 32
08/03/2025 09:10:15 PM Learning rate: 0.001
08/03/2025 09:10:15 PM Step 1: Creating data splits...
08/03/2025 09:10:15 PM Exception raised in setup_training_pipeline. exception: '/Users/adonisserrano/Documents/GitHub/aquatic-life-classifier/data/processed/kaggle.Lobster/kaggle.Lobster_469.jpg' and '/Users/adonisserrano/Documents/GitHub/aquatic-life-classifier/data/processed/kaggle.Lobster/kaggle.Lobster_469.jpg' are the same file
Traceback (most recent call last):
  File "/Users/adonisserrano/Documents/GitHub/aquatic-life-classifier/src/utils/management/decorators.py", line 57, in wrapper
    res = func(*args, *kwargs)
  File "/Users/adonisserrano/Documents/GitHub/aquatic-life-classifier/src/data_pipeline/pipeline_service.py", line 157, in setup_training_pipeline
    create_data_splits(config['source_data_dir'], config['split_data_dir'])
  File "/Users/adonisserrano/Documents/GitHub/aquatic-life-classifier/src/data_pipeline/utils/data_helpers.py", line 170, in create_data_splits
    shutil.copy2(data_file_source, data_file_dest)
  File "/Users/adonisserrano/opt/anaconda3/envs/sea-life-classifier/lib/python3.9/shutil.py", line 444, in copy2
    copyfile(src, dst, follow_symlinks=follow_symlinks)
  File "/Users/adonisserrano/opt/anaconda3/envs/sea-life-classifier/lib/python3.9/shutil.py", line 244, in copyfile
    raise SameFileError("{!r} and {!r} are the same file".format(src, dst))
shutil.SameFileError: '/Users/adonisserrano/Documents/GitHub/aquatic-life-classifier/data/processed/kaggle.Lobster/kaggle.Lobster_469.jpg' and '/Users/adonisserrano/Documents/GitHub/aquatic-life-classifier/data/processed/kaggle.Lobster/kaggle.Lobster_469.jpg' are the same file
